<mujoco model="rube_goldberg_machines">


  <visual>
    <headlight diffuse="0.6 0.6 0.6"  ambient="0.3 0.3 0.3" specular="0 0 0"/>
    <rgba haze="0.15 0.25 0.35 1"/>
    <global azimuth="120" elevation="-20" realtime="1.0"/>
  </visual>

  <asset>
    <texture type="skybox" builtin="gradient" rgb1="0.3 0.5 0.7" rgb2="0 0 0" width="512"
        height="3072"/>
    <texture type="2d" name="groundplane" builtin="checker" mark="edge" rgb1="0.2 0.3 0.4"
        rgb2="0.1 0.2 0.3" markrgb="0.8 0.8 0.8" width="300" height="300"/>
    <material name="groundplane" texture="groundplane" texuniform="true" texrepeat="5 5"
        reflectance="0.1"/>
  </asset>

  <worldbody>
    <geom name="floor" size="0 0 0.05" type="plane" material="groundplane"/>

    <body pos="0.0 0.2 0.2" euler="0 45 0" name="red_slide">
      <geom  type="box" size="0.1 0.2 0.2" rgba="1 0 0 1"  solref="-10000 -10"/>
    </body>

    <body pos="-1 0.2 0.2" euler="0 0 45" name="red_slide_2">
      <geom  type="box" size="0.1 0.2 0.2" rgba="1 0 0 1"  solref="-10000 -10"/>
    </body>

    <body pos="-1 1.2 0.2" euler="0 0 -45" name="red_slide_3">
      <geom  type="box" size="0.1 0.2 0.2" rgba="1 0 0 1"  solref="-10000 -10"/>
    </body>

    <body pos="1 1.2 0.2" euler="0 0 -45" name="red_slide_4">
      <geom  type="box" size="0.1 0.2 0.2" rgba="1 0 0 1"  solref="-10000 -10"/>
    </body>

    <body pos="0.9 2.8 0.3" euler="0 0 0" name="kick_bar">
      <geom  type="box" size="0.2 0.02 0.3" rgba="1 0 0 1"  solref="-10000 -10"/>
      <freejoint/>
    </body>

    <body pos="0.9 3.2 0.3" euler="0 0 0" name="kick_bar2">
      <geom  type="box" size="0.2 0.02 0.3" rgba="1 0 0 1"  solref="-10000 -10"/>
      <freejoint/>
    </body>

    <body pos="0.9 3.6 0.3" euler="0 0 0" name="kick_bar3">
      <geom  type="box" size="0.2 0.02 0.3" rgba="1 0 0 1"  solref="-10000 -10"/>
      <freejoint/>
    </body>

    <body pos="0.9 4.0 0.3" euler="0 0 0" name="kick_bar4">
      <geom  type="box" size="0.2 0.02 0.3" rgba="1 0 0 1"  solref="-10000 -10"/>
      <freejoint/>
    </body>

    <body pos="0.9 4.4 0.5" euler="0 0 0" name="kick_bar5">
      <geom  type="box" size="0.2 0.02 0.5" rgba="1 0 0 1"  solref="-10000 -10" mass="350"/>
      <freejoint/>
    </body>


    <body pos="0.9 5.2 0.45" euler="0 0 0" name="drop_cylinder1">
      <geom  type="cylinder" size="0.12 0.45" rgba="1 0 0 1"  solref="-10000 -10" mass="100"/>
      <freejoint/>
    </body>


    <body pos="0.9 5.2 7.7" euler="0 0 0" name="drop_cylinder2">
      <geom  type="cylinder" size="0.1 6.7" rgba="1 0 0 1"  solref="-10000 -10" friction="0 0 0"/>
      <geom pos="0 0 -6.75" type="cylinder" size="0.1 0.05" rgba="1 1 0 1"  solref="-10000 -10" />
      <freejoint/>
    </body>



    <body name="holed_plate" pos="0.9 5.2 13.0">
      <geom pos="0 -0.20 0" size="0.6 0.1 0.5" type="box" group="0" rgba="0 1 1 1" />
      <geom pos="0 0.20 0" size="0.6 0.1 0.5" type="box" group="0" rgba="0 0 1 1" />
      <geom pos="-0.35 0 0" size="0.25 0.1 0.5" type="box" group="0" rgba="0 1 0 1" />
      <geom pos="0.35 0 0" size="0.25 0.1 0.5" type="box" group="0" rgba="1 0 0 1" />

      <geom pos="-0.7 0 0.4" type="box" size="0.1 0.3 0.5" rgba="0 1 0 1"  solref="-10000 -10"/>
      <geom pos="0.7 0 0.4" type="box" size="0.1 0.3 0.5" rgba="0 1 0 1"  solref="-10000 -10"/>
    </body>

    <body pos="0.9 7.1 13.0" euler="-10 0 0" name="ball_line_bottom">
      <geom  type="box" size="0.6 1.6 0.1" rgba="0 1 0 1"  solref="-10000 -10"/>
      <geom pos="-0.7 0 0" type="box" size="0.1 1.6 0.6" rgba="0 1 0 1"  solref="-10000 -10"/>
      <geom pos="0.7 0 0" type="box" size="0.1 1.6 0.6" rgba="0 1 0 1"  solref="-10000 -10"/>
    </body>

    <body pos="0.9 2.0 16.1" euler="-45 0 0" name="ball_line_up">
      <geom  type="box" size="0.6 3.6 0.1" rgba="0 1 0 1"  solref="-10000 -10"/>
      <geom pos="-0.7 0 0" type="box" size="0.1 3.6 0.6" rgba="0 1 0 1"  solref="-10000 -10"/>
      <geom pos="0.7 0 0" type="box" size="0.1 3.6 0.6" rgba="0 1 0 1"  solref="-10000 -10"/>
    </body>

    <body pos="0.9 4.6 14.9" name="big_sphere">
      <geom  size="0.7" rgba="1 0 1 1" solref="-10000 -10" density="340" />
      <freejoint/>
    </body>


    <body pos="0.9 15.6 2.6" euler="-30 0 0">
      <geom  type="box" size="0.6 4.8 0.2" rgba="0 1 0 1"  solref="-10000 -10" mass = "1"/>
      <joint name="J1" type="hinge" pos="0 -1.6 0" axis="1 0 0"  limited="true" range="0 60"/>
      <body pos="0 4.2 0.40" >
        <geom pos=" 0.6 0   0" type="box" size="0.1 0.6 0.2" rgba="1 1 0 1" mass="1"/>
        <geom pos="-0.6 0   0" type="box" size="0.1 0.6 0.2" rgba="1 1 0 1" mass="1"/>
        <geom pos=" 0   0.6 0" type="box" size="0.6 0.1 0.6" rgba="1 1 0 1" mass="1"/>
        <geom pos=" 0  -0.6 0" type="box" size="0.6 0.1 0.2" rgba="1 1 0 1" mass="1"/>
      </body>
    </body>

    <body pos="0.9 19.55 1.1" name="throw_ball">
      <freejoint/>
      <geom  size="0.4" rgba="1 1 0 1" solref="-10000 -10" density="140" />
    </body>


    <body pos="0.02 0.2 5" name="green_sphere">
      <freejoint/>
      <geom  size="0.05" rgba="0 1 0 1" solref="-10000 -10" density="1340" />
    </body>


    <body pos="0.9 -30 20" name="box_to_down" >
      <geom  type="box" size="4 1 20" rgba="1 1 1 1" mass="9"/>
      <freejoint/>
    </body>



  </worldbody>

</mujoco>
